Workbook

Sheet All Circle
B3: REPORT ACCUMULATION ACHIEVEMENT PROMOTOR
B4: Region | C4: RGE | D4: Area Penempatan | E4: Jumlah Promotor | F4: Edukasi Total | G4: Rebuy Total | H4: Akuisisi Total
B5: Central Java | C5: Yogie | D5: Yogyakarta | E5: 5 | F5: 309 | G5: 4 | H5: 49
C6: Fitri | D6: Solo | E6: 4 | F6: 299 | G6: 13 | H6: 57
C7: Wahyudi | D7: Semarang | E7: 6 | F7: 388 | G7: 32 | H7: 61
C8: Lingga | D8: Sleman | E8: 4 | F8: 41 | G8: 23 | H8: 36
C9: TOTAL | E9: 19 | F9: 1037 | G9: 72 | H9: 203
B10: East Java | C10: Melody | D10: Surabaya | E10: 7 | F10: 56 | G10: 36 | H10: 22
C11: Fendi | D11: Malang | E11: 5 | F11: 227 | G11: 34 | H11: 48
C12: Rizal | D12: Jember | E12: 5 | F12: 133 | G12: 6 | H12: 16
C13: TOTAL | E13: 17 | F13: 416 | G13: 76 | H13: 86
B14: Bali Nusra | C14: Maria | D14: Denpasar | E14: 4 | F14: 10 | G14: 0 | H14: 0
C15: Dewa | D15: Gianyar | E15: 2 | F15: 4 | G15: 2 | H15: 0
C16: Diswan | D16: Badung | E16: 2 | F16: 0 | G16: 0 | H16: 0
C17: Afan | D17: Singaraja | E17: 2 | F17: 0 | G17: 0 | H17: 0
C18: TOTAL | E18: =SUM(E14:E17) -> 10 | F18: =SUM(F14:F17) -> 14 | G18: =SUM(G14:G17) -> 2 | H18: =SUM(H14:H17) -> 0
B19: Total Circle Java | E19: =SUM(E9+E13+E18) -> 46 | F19: =F9+F13+F18 -> 1467 | G19: =G18+G13+G9 -> 150 | H19: =H18+H13+H9 -> 289
B23: REPORT ACHIEVEMENT PROMOTOR - 30 JUNI 2026
B24: Region | C24: RGE | D24: Area Penempatan | E24: Jumlah Promotor | F24: Edukasi Total | G24: Rebuy Total | H24: Akuisisi Total
B25: Central Java | C25: Yogie | D25: Yogyakarta | E25: 5 | F25: 309 | G25: 4 | H25: 49
C26: Fitri | D26: Solo | E26: 4 | F26: 299 | G26: 13 | H26: 57
C27: Wahyudi | D27: Semarang | E27: 6 | F27: 388 | G27: 32 | H27: 61
C28: Lingga | D28: Sleman | E28: 4 | F28: 41 | G28: 23 | H28: 36
C29: TOTAL | E29: 19 | F29: 1037 | G29: 72 | H29: 203
B30: East Java | C30: Melody | D30: Surabaya | E30: 7 | F30: 56 | G30: 36 | H30: 22
C31: Fendi | D31: Malang | E31: 5 | F31: 227 | G31: 34 | H31: 48
C32: Rizal | D32: Jember | E32: 5 | F32: 133 | G32: 6 | H32: 16
C33: TOTAL | E33: 17 | F33: 416 | G33: 76 | H33: 86
B34: Bali Nusra | C34: Maria | D34: Denpasar | E34: 4 | F34: 10 | G34: 0 | H34: 0
C35: Dewa | D35: Gianyar | E35: 2 | F35: 4 | G35: 2 | H35: 0
C36: Diswan | D36: Badung | E36: 2 | F36: 0 | G36: 0 | H36: 0
C37: Afan | D37: Singaraja | E37: 2 | F37: 0 | G37: 0 | H37: 0
C38: TOTAL | E38: =SUM(E34:E37) -> 10 | F38: =SUM(F34:F37) -> 14 | G38: =SUM(G34:G37) -> 2 | H38: =SUM(H34:H37) -> 0
B39: Total Circle Java | E39: =SUM(E29+E33+E38) -> 46 | F39: =F29+F33+F38 -> 1467 | G39: =G38+G33+G29 -> 150 | H39: =H38+H33+H29 -> 289
B43: REPORT ACHIEVEMENT PROMOTOR - 07 JULI 2026
B44: Region | C44: RGE | D44: Area Penempatan | E44: Jumlah Promotor | F44: Edukasi Total | G44: Rebuy Total | H44: Akuisisi Total
B45: Central Java | C45: Yogie | D45: Yogyakarta | E45: 5 | F45: 267 | G45: 5 | H45: 37
C46: Fitri | D46: Solo | E46: 4 | F46: 104 | G46: 22 | H46: 15
C47: Wahyudi | D47: Semarang | E47: 6 | F47: 547 | G47: 72 | H47: 91
C48: Lingga | D48: Sleman | E48: 4 | F48: 100 | G48: 2 | H48: 21
...

Sheet Form Responses 1
A1: Timestamp | B1: Hari & Tanggal | C1: Region | D1: Area Penempatan | E1: Nama Promotor | F1: Nama Outlet | G1: Upload Foto Kehadiran dengan Time Stamp (untuk Bukti Kehadiran) | H1: Jumlah edukasi - isi dengan angka. Cth: 2 (Target 30 hari: 600 edukasi Gemini) | I1: Bukti Foto Edukasi | J1: Jumlah penjualan Kartu Perdana - isi dengan angka. Cth: 2 (Target 30 hari: 100 Kartu Perdana terjual) | K1: Jumlah penjualan Paket Isi Ulang - isi dengan angka. Cth: 2 (Target 30 hari: 200 Paket Isi Ulang terjual) | L1: Bukti Foto Penjualan | M1: List No. HP yang terjual | N1: List No. HP yang melakukan isi ulang | O1: Upload Foto Kepulangan dengan Time Stamp (untuk Bukti Kepulangan) | P1: Jumlah aktivasi Gemini dari orang yang diedukasi | Q1: Hari & Tanggal 2 | R1: Brand | S1: Column 1 | T1: Column 20
A2: 46204.859 | B2: 46204 | C2: East Java (Jatim) | D2: Surabaya | E2: Adit | F2: Axoo Cell | G2: https://drive.google.com/open?id=1ccOL6O0qsZ-h7GEBmipzs5VF9_fU9UdS | H2: 15 | J2: 1 | K2: 2 | L2: https://drive.google.com/open?id=1z4SVoYWE52ZAQ2h8WINT3YU4c1HJwC1W | M2: 089684210008 | N2: 085606633231 | O2: https://drive.google.com/open?id=1eNqXWrNDv_TnHPJ4gi2yqCPCrKy3kLYH | P2: 1
A3: 46205.717 | B3: 46205 | C3: East Java (Jatim) | D3: Surabaya | E3: Adit | F3: Axoo | G3: https://drive.google.com/open?id=1pP1PFCL5MvYSTvJesoC3RTaMulxyzc1Y | H3: 15 | J3: 1 | K3: 2 | L3: https://drive.google.com/open?id=1Zf154JzyIsnKcCjoaiMDj6smMORMmE10 | M3: 085801200180 | N3: 085859545417 | O3: https://drive.google.com/open?id=1d6-B-E9J0gX_4S5aKXSfyt9Wo1iPv_I8 | P3: 3
A4: 46206.87 | B4: 46206 | C4: East Java (Jatim) | D4: Surabaya | E4: Adit | F4: Axoo | G4: https://drive.google.com/open?id=1kmvtKpGqoZS-l2lGYqb5Kt_uG3Vhv2WQ | H4: 17 | J4: 0 | K4: 4 | L4: https://drive.google.com/open?id=1_tD0mxEcrlbuLrIMTVYoJc_zWA4SI3Dp | M4: 0 | N4: 1. 085733621125 2. 085749549485 3. 085645452029 4. 085773769634 | O4: https://drive.google.com/open?id=1XMWLLwp8sYDmiZfqc4ml80Iy5XFmhoHG | P4: 0
A5: 46209.5 | B5: 46207 | C5: East Java (Jatim) | D5: Surabaya | E5: Adit | F5: Axoo | G5: https://drive.google.com/open?id=10Giv1XZ8ISnD-FUHIKK2O2xsauGpe6XE | H5: 18 | J5: 0 | K5: 3 | L5: https://drive.google.com/open?id=1ZFWTkFy0SqW6AuzhSBtMs15gmi93Vn1w | M5: 0 | N5: 1. 089504744464 2. 085536930726 3. 0895399488277 | O5: https://drive.google.com/open?id=1tblnvsy7V_eeK8REceVd2XhOFXGuQDWd | P5: 0
A6: 46209.503 | B6: 46208 | C6: East Java (Jatim) | D6: Surabaya | E6: Adit | F6: Axoo | G6: https://drive.google.com/open?id=1RlOpJEm8ofct5timSYMFlt1rNSX0aXBA | H6: 19 | J6: 2 | K6: 4 | L6: https://drive.google.com/open?id=1xuZtx1naQDp3wkPPgrUNQgafjg-sKTs2 | M6: 085732317400 | N6: 1. 085732317400 2. 085806042745 3. 08574177532 4. 089507312455 | O6: https://drive.google.com/open?id=1bdKbl-eyqe8HFVvOXN4AN43wYnocTmod | P6: 0
A7: 46209.828 | B7: 46209 | C7: East Java (Jatim) | D7: Surabaya | E7: Adit | F7: Axoo | G7: https://drive.google.com/open?id=1d0LsUXNfizhT_DdhdXZ7lgxDX6QWEaAQ | H7: 13 | J7: 2 | K7: 6 | L7: https://drive.google.com/open?id=1V0RLsshcbPnVsZ2_tmWop5hsAkVAxtAM | M7: 085600627931 | N7: 085859545417 | O7: https://drive.google.com/open?id=1Y9HypKMoyK4jtoK018cY-DiJrZcOaKUr | P7: 0
A8: 46210.761 | B8: 46210 | C8: East Java (Jatim) | D8: Surabaya | E8: Adit | F8: Axoo | G8: https://drive.google.com/open?id=10HznNW7UBxz1q8l_1rTim23LX_on83jv | H8: 20 | J8: 4 | K8: 7 | L8: https://drive.google.com/open?id=1SPzPQEbJgSuA4v9mG0P2UfZ91MrpFD6g | M8: 0895634210633 | N8: 085755857899 | O8: https://drive.google.com/open?id=1LhJiPiK4SCVm78PwMiSf8erVINOog32v | P8: 0
A9: 46203.815 | B9: 46203 | C9: East Java (Jatim) | D9: Malang | E9: aulia farah | F9: joker cell | G9: https://drive.google.com/open?id=1YFeZ9gk3zAR2gUqvBJfb37HYXITqOVpF | H9: 20 edukasi gemini di kampus | J9: 0 | K9: 5 | L9: https://drive.google.com/open?id=1BBcgB4uGJ7kXoidEP7LYlTeD5F-deJGd | M9: 0 | N9: 08564515 4944 085791943323 0895 42 37 13578 0895639052073 085806555510 | O9: https://drive.google.com/open?id=1KYCYjs9raBFhFi5MYJdOjEeborPg04f7 | P9: 5
A10: 46205.47 | B10: 46204 | C10: East Java (Jatim) | D10: Malang | E10: aulia farah | F10: Joker Cell | G10: https://drive.google.com/open?id=1b7aGPzXPgZFexnXlOQEijf5iNBo2urSv | H10: 23 | J10: 0 | K10: 9 | L10: https://drive.google.com/open?id=1suvHRBrZqhg93B3_bWUcaIbTqilKf_Hl | M10: 0 | N10: 0895411958998 0895402526994 085646539945 085741116861 0856 04427779 08563423235 087856955350 085649272163 085738677184 085730127697 085730127697 | O10: https://drive.google.com/open?id=1dmCE41-tobTZhqXyLfPyzsAWQSKbglwY | P10: 13
A11: 46206.597 | B11: 46205 | C11: East Java (Jatim) | D11: Malang | E11: aulia farah | F11: joker cell | G11: https://drive.google.com/open?id=1O9TF1e9NajKkRGH5gYb7ki7V7mfzyvYe | H11: 27 | J11: 0 | K11: 10 | L11: https://drive.google.com/open?id=1l2d3_N0ZRfFObyrZ5028p-Ld3bXZq2Gv | M11: 0 | N11: 085649720018 085707964322 087842221767 085743474651 087812271027 085852903096 08989894602 085854370752 085701754071 085707964322 | O11: https://drive.google.com/open?id=1YnyyX0uk2TsPolRALJLkkfzJbRQgNRAe | P11: 13
A12: 46205.752 | B12: 46205 | C12: Central Java (Jateng) | D12: Semarang | E12: Bagus Nurul Khamid | F12: King Tronik 2 | G12: https://drive.google.com/open?id=1ptFOwcEdsuaE1u-5NPTnrCs41k4xrhBB | H12: 10 | J12: 1 | K12: 3 | L12: https://drive.google.com/open?id=1s5A23fhoQXag_Np41E0Sn_AmwtiAOI98 | M12: 0895622995017 | N12: 089602333258 089602338594 085725110191 | O12: https://drive.google.com/open?id=15VEFiXchewIvCDCmkfAjq1DdkdZhfUU2 | P12: 8
A13: 46206.815 | B13: 46206 | C13: Central Java (Jateng) | D13: Semarang | E13: Bagus Nurul Khamid | F13: Area semarang selatan | G13: https://drive.google.com/open?id=1qOeb0Ri8k3_YJkeo0VbCslkOevyzc_GL | H13: * 8 | J13: * 2 | K13: *0 | L13: https://drive.google.com/open?id=1tAf5dKeVd7SNvoX4mqsub7sHd0AbC4OJ | M13: 1.089673499234 2. 0895634252328 | N13: *0 | O13: https://drive.google.com/open?id=1gjS8pZYc6-gNFQSk-GByhtMt0cr6d022 | P13: * 2
A14: 46209.501 | B14: 46208 | C14: Central Java (Jateng) | D14: Semarang | E14: Bagus Nurul Khamid | F14: King Tronik 2 | G14: https://drive.google.com/open?id=1VMd7uuzPN2QaEQcLnYsdCKKawxrlGuYa | H14: *8 | J14: *0 | K14: *0 | M14: *0 | N14: *0 | O14: https://drive.google.com/open?id=1DI-LFeWXAZKtDtjlLq7xntF8AWljNCZz | P14: *0
A15: 46209.828 | B15: 46209 | C15: Central Java (Jateng) | D15: Semarang | E15: Bagus Nurul Khamid | F15: King Tronik 2 | G15: https://drive.google.com/open?id=1UJQ9sVOvviMHO9KVx53aMmBz0ahMwMle | H15: 4 | J15: 1 | K15: 0 | L15: https://drive.google.com/open?id=1h8tcQg_3K9qS-RNaJWew-YBRL4z8mKY3 | M15: 089673499060 | N15: 0 | O15: https://drive.google.com/open?id=17u7JCJMyBZ0fpgtUdJknpl2f3PZk3IAw | P15: 3
A16: 46210.91 | B16: 46210 | C16: Central Java (Jateng) | D16: Semarang | E16: Bagus Nurul Khamid | F16: King Tronik 2 | G16: https://drive.google.com/open?id=1ozmAyV4Jq4laNpo_e5TTCBw_g6ALDJTI | H16: 9 | J16: 1 | K16: 1 | L16: https://drive.google.com/open?id=1efdeYMSA29UzuSRhu_WDozMWVL_7kW_f | M16: 089673499060 | N16: 089654354838 | O16: https://drive.google.com/open?id=1n8jJ10CZ20V-szo8IQw3N2S2xgsg342H | P16: 3
A17: 46203.718 | B17: 46203 | C17: East Java (Jatim) | D17: Malang | E17: Destya Kamilia | F17: Prasanjaya | G17: https://drive.google.com/open?id=15XLaHVT6344HbUUaU_tpfvFghPuvsmUP | H17: 26 | J17: 0 | K17: 1 | L17: https://drive.google.com/open?id=1T6I1QM9tE9mVo5ZhXdTO4BiCZtY-YsJt | M17: 0 | N17: 089696877803 | O17: https://drive.google.com/open?id=1s4zAe9Z1BL3S6RMLZS15P7kxe3pFEALd | P17: 1
A18: 46204.756 | B18: 46204 | C18: East Java (Jatim) | D18: Malang | E18: Destya Kamilia | F18: Prasanjaya | G18: https://drive.google.com/open?id=1DFBoH9NuybQZwxveJC_4MugC_F5gERtv | H18: 32 | J18: 1 | K18: 7 | L18: https://drive.google.com/open?id=11jZMBMSewGPIFNL4X-bPXX6w2PzECMM3 | M18: 085738234995 | N18: 0895422419006, 085748341045, 0857855665693, 085733190124, 085878074185, 085731146817, 085693599846 | O18: https://drive.google.com/open?id=1E8MnvmXq977i0hskQ10LmX9qvqIjgl9g | P18: 5
A19: 46205.667 | B19: 46205 | C19: East Java (Jatim) | D19: Malang | E19: Destya Kamilia | F19: Prasanjaya | G19: https://drive.google.com/open?id=1GFyMwR3g2m-Z9cjc9mj8XguaIMtTD8Uq | H19: 44 | J19: 2 | K19: 6 | L19: https://drive.google.com/open?id=1jVV_vHExYS0oHT9rMVJhh0bYTR34O5Gn | M19: 085706883379, 085738234990 | N19: 0895403802132, 085732743451, 085710645629, 085706707880, 085784280162, 085732743451 | O19: https://drive.google.com/open?id=1sI3bQyv2-wubbWmWWcHynwlW-gCfPoAT | P19: 1
A20: 46206.731 | B20: 46206 | C20: East Java (Jatim) | D20: Malang | E20: Destya Kamilia | F20: Prasanjaya | G20: https://drive.google.com/open?id=1YS-bxN-l0wxy33THHQ1Njc1z44Vjamr5 | H20: 23 | J20: 0 | K20: 6 | L20: https://drive.google.com/open?id=1kcm1p-XIGSMisqa1TODR4hCOmBH3TSEX | M20: 0 | N20: 08976460818, 08983330546, 085732743457, 085875113418, 085649140765, 08970520811 | O20: https://drive.google.com/open?id=1TlnlOStGRsQpeKHXLgZfJmbYSfS5-TpJ | P20: 4
A21: 46209.383 | B21: 46207 | C21: East Java (Jatim) | D21: Malang | E21: Destya Kamilia | F21: Prasanjaya Oulet | G21: https://drive.google.com/open?id=1ILj8WFkbiFAkzvXMcnai-1kNec63olJA | H21: 26 | J21: 0 | K21: 1 | L21: https://drive.google.com/open?id=1ufEgi6FeIfsVv-4jWyyzIX2cnGX4VFM7 | M21: 0 | N21: 085748341045 | O21: https://drive.google.com/open?id=12EznUPtNDEhAE2A3FrQk9EcSUqEPIYRp | P21: 3
A22: 46209.67 | B22: 46209 | C22: East Java (Jatim) | D22: Malang | E22: Destya Kamilia | F22: Prasanjaya | G22: https://drive.google.com/open?id=1MSxlbdyuZRtctdDNY0ZAlXE2b44KCllF | H22: 35 | J22: 0 | K22: 10 | L22: https://drive.google.com/open?id=1I0qNpNtYsN4LHl17JoDXRj4LPEcyBbV5 | M22: 0 | N22: 089672931460, 085732743451, 085743593774, 085732743451, 085852982780, 085692124364, 085647455172, 08970520811, 08976460818, 08976460818(2x) | O22: https://drive.google.com/open?id=1LM-1_OKv3apzvpJvknrAJfBsUEyfnayN | P22: 2
A23: 46210.69 | B23: 46210 | C23: East Java (Jatim) | D23: Malang | E23: Destya Kamilia | F23: Prasanjaya | G23: https://drive.google.com/open?id=1_hToEA1MgSx59SjZzDEVoxck553nYlL5 | H23: 28 | J23: 1 | K23: 2 | L23: https://drive.google.com/open?id=1p4NOGffBxy5UlNV5Dz1j-XYyw8SRUKJs | M23: 085706780196 | N23: 0896363880119, 089678203326 | O23: https://drive.google.com/open?id=1y8lG_79Anz6UZXoTmNkHu8NFvJXjXjER | P23: 4
A24: 46205.762 | B24: 46205 | C24: Central Java (Jateng) | D24: Semarang | E24: Devi kumala novianti | F24: Semarang | G24: https://drive.google.com/open?id=1ufday6VpH6jJ70WIqK5up39BEXtzv0N8 | H24: 20 | J24: 0 | K24: 0 | L24: https://drive.google.com/open?id=1bo7oWrYt4tDw0ACDBFoV_VU1WncLS0HA | M24: 0 | N24: 0 | O24: https://drive.google.com/open?id=1ThoO1n--rtL3qr964FbUNA79XzaXbsaS | P24: 7
A25: 46206.875 | B25: 46206 | C25: Central Java (Jateng) | D25: Semarang | E25: Devi kumala novianti | F25: Aristo | G25: https://drive.google.com/open?id=1lBkuIKFCxm_sAhGnmHmfWF-nru43w09m | H25: 21 | J25: 1 | K25: 0 | L25: https://drive.google.com/open?id=1pSkM4NFeERqKPp_YxB1GmifJiStwJ31o | M25: 0895622989306 | N25: 0 | O25: https://drive.google.com/open?id=1fPZd5danS3zON9d6v285XBBaOxDqsQ5k | P25: 14
A26: 46209.379 | B26: 46207 | C26: Central Java (Jateng) | D26: Semarang | E26: Devi kumala novianti | F26: Aristo cell | G26: https://drive.google.com/open?id=1FjnT-WpWKcJzizec_ndC-TylHrf29yLZ | H26: 30 | J26: 2 | K26: 10 | L26: https://drive.google.com/open?id=1VgVIkMVNLwcH2gmNl7Oncn0vSb6olPcy | M26: 089671862745 , 0895622989339 | N26: 089609263939, 0895403151465, 08988105485, 0895428845053, 081460401468, 0857-4027-5549, 0895346194409, 0896-5360-2383 | O26: https://drive.google.com/open?id=117F_2ckmByK4B8NjV6HuYRtz2yS45crb | P26: 20
A27: 46209.893 | B27: 46209 | C27: Central Java (Jateng) | D27: Semarang | E27: Devi kumala novianti | F27: Aristo | G27: https://drive.google.com/open?id=1nwf9lwZ_QWifA_q7qhneOgB4c-AoKu07 | H27: 26 | J27: 1 | K27: 8 | L27: https://drive.google.com/open?id=1FtIXd8EnxID4EV15nzGIUKROk9MaIxQb | M27: 0895622998057 | N27: 0895400754428 , 0895-0194-3010 , 089521401942, 08988150557, 0895622190587, 0895414352305, 085815018400, 089693817430 | O27: https://drive.google.com/open?id=1VmReSCvbuSJPSnxLPO-gNW5cnBH6-NJ3 | P27: 13
A28: 46210.778 | B28: 46210 | C28: Central Java (Jateng) | D28: Semarang | E28: Devi kumala Novianti | F28: Aristo | G28: https://drive.google.com/open?id=1ven4XjWfV0fnB_eQFalUE6qv49u-kp3- | H28: 29 | J28: 3 | K28: 5 | L28: https://drive.google.com/open?id=1tekI-R36tjEMh4UZVlFt-s-6o2f1m-Dz | M28: 089671862742, 0895622989305, 0895622989319 | N28: 089515479988, 089682579549, 085713033435, 0895422570874, 089688049896 | O28: https://drive.google.com/open?id=1hlAJxHVjOE8gYP-5JlhOs1_ufl7xo-CU | P28: 14
A29: 46202.835 | B29: 46202 | C29: East Java (Jatim) | D29: Jember | E29: Dewi Kumalasari | F29: Gazwah 2 | G29: https://drive.google.com/open?id=1v-PJACEVbuCV5VY1UV_QEQN4VN9oZ7AR | H29: 11 | J29: 3 | K29: 0 | L29: https://drive.google.com/open?id=1UlUE5jdaZXShGGnnu7IwTENR86A8t5Gl | M29: 085601242892, 085601243893, 085601242898 | N29: 0 | O29: https://drive.google.com/open?id=1TR0J4ERtj0DP0NKjdw0f5S-eoZ3c1V8X | P29: 3
A30: 46203.783 | B30: 46203 | C30: East Java (Jatim) | D30: Jember | E30: Dewi Kumalasari | F30: Gazwah 2 | G30: https://drive.google.com/open?id=1huLYprj-tZHTe50pcEVu-CAOvGvrqUpl | H30: 27 | J30: 0 | K30: 0 | L30: https://drive.google.com/open?id=1owE6thnyG4e5SozAllMYrL1wTgG4pLqh | M30: 0 | N30: 0 | O30: https://drive.google.com/open?id=1CHlNpsshA-KEUAhe2TwuLWcSqeNX1oca | P30: 0
A31: 46204.796 | B31: 46204 | C31: East Java (Jatim) | D31: Jember | E31: Dewi Kumalasari | F31: Gazwah 2 | G31: https://drive.google.com/open?id=1B8chfwGowqW0GnGzLoaKq7s4D3g1KwnK | H31: 32 orang (ada beberapa yang tidak terfoto karena ada beberapa yang tidak mau) | J31: 0 | K31: 1 rebuy pulsa, 1 voucher | L31: https://drive.google.com/open?id=1voX_O-cHGxwTeVhS417lqH2XY06jxa1x | M31: 0 | N31: 081515835028 | O31: https://drive.google.com/open?id=1qBJZr2R8HgCdKx553f2_nx1SMKvtAWUY | P31: 7
A32: 46205.82 | B32: 46205 | C32: East Java (Jatim) | D32: Jember | E32: Dewi Kumalasari | F32: Gazwah 2 | G32: https://drive.google.com/open?id=1u9KDnHadq3oKrAfIt4AOPRUvJof8y3Nw | H32: 44 | J32: - | K32: - isi ulang data 1 (tri). - isi ulang pulsa 2 (IM3) , voucher 5 | L32: https://drive.google.com/open?id=1bgoXNNvEhVUrXPN4JXpNG22m5c0Vsueu | M32: - | N32: 089514978481, 081515835028, 085853262146 | O32: https://drive.google.com/open?id=1XNWk20nFEkpGUlOUabbNQrGD5R36xMCy | P32: 7
A33: 46206.819 | B33: 46206 | C33: East Java (Jatim) | D33: Jember | E33: Dewi Kumalasari | F33: gazwah 2 | G33: https://drive.google.com/open?id=11Nn5pWSfXAs0bEKQyU07oI83GpcudPPc | H33: 20 | J33: 2 | K33: voucher 5 | L33: https://drive.google.com/open?id=1lEfR19WuOKrsMecn797T3GVD4f-3zyRz | M33: 085641119022, 085641118997 | N33: - | O33: https://drive.google.com/open?id=1W-tstGIbEeSbnzb453LtfJfTuEpbdzY0 | P33: 6
A34: 46210.697 | B34: 46208 | C34: East Java (Jatim) | D34: Jember | E34: Dewi Kumalasari | F34: Gazwah 2 | G34: https://drive.google.com/open?id=1SU9hnyve91ubwMLoUZemARU92LctEePD | H34: 21 | J34: 3 | K34: 19, voucher 18, isi ulang pulsa 1 | L34: https://drive.google.com/open?id=1lHVsDHWP5EsZnNhfSn-l2LLMOlwhIh9B | M34: 085641118994, 089682005144, 085641118952 | N34: 085875411136 | O34: https://drive.google.com/open?id=1KLQh8OOHMdsUKPtdC1qkq33E8JIWEw9t | P34: 8
A35: 46210.699 | B35: 46209 | C35: East Java (Jatim) | D35: Jember | E35: Dewi Kumalasari | F35: gazwah 2 | G35: https://drive.google.com/open?id=1trOpM8KfN-i2s1mguF84SGOMmAa43Esg | H35: 34 | J35: 2 | K35: voucher 5 | L35: https://drive.google.com/open?id=1NCo18tzgU7dMAlvg-_8PtBXIJ9wIMxF4 | M35: 085641118993, 085641118894 | N35: - | O35: https://drive.google.com/open?id=1p5NPQ83wH3nQWxjwswQ6AMCMSyJ9-Q22 | P35: 9
A36: 46210.701 | B36: 46210 | C36: East Java (Jatim) | D36: Jember | E36: Dewi Kumalasari | F36: gazwah 2 | G36: https://drive.google.com/open?id=1kIgMuWBIYGD2FaP2k5DNFw2P3UFggCyl | H36: 22 | J36: 1 | K36: voucher 1 | L36: https://drive.google.com/open?id=1UvhRhm3a4YYPfSOISVLrCzA2tdDKTD-m | M36: 085641118942 | N36: - | O36: https://drive.google.com/open?id=11-0M__41-VDWJe1dylwxBDXwzWCiFnXB | P36: 5
A37: 46204.925 | B37: 46204 | C37: East Java (Jatim) | D37: Surabaya | E37: Dimas | F37: Savira cell | G37: https://drive.google.com/open?id=1NOv6eQ0iclyH2l4RqOorojd8_Zo9Qatl | H37: 6 | J37: 0 | K37: 1 | L37: https://drive.google.com/open?id=12bEUa3HN5GevhbOb2B1jKGecoKrdgy7z | M37: 085737017953 | N37: 085737017953 | O37: https://drive.google.com/open?id=1ETkOJCgpMMbqb90iRloJtYtiyhfZA51E | P37: 2
A38: 46205.851 | B38: 46205 | C38: East Java (Jatim) | D38: Surabaya | E38: DIMAS | F38: Savira cell | G38: https://drive.google.com/open?id=1I7MdHDcuRhN662oK94dWv-NQAOgVMvE8 | H38: 9 | J38: 0 | K38: 1 | L38: https://drive.google.com/open?id=1SJrFXfU6c68lj0aWbmjqcQnt1Br7is6a | M38: 0 | N38: 085748587728 | O38: https://drive.google.com/open?id=18zIwk_TNW7-xeqOhZ0fKo5cF6t3R0Fvj | P38: 4
A39: 46206.938 | B39: 46206 | C39: East Java (Jatim) | D39: Surabaya | E39: Dimas | F39: Savira cell | G39: https://drive.google.com/open?id=1-brV3os7kzsupGug6mC9Ympi42psBX49 | H39: 9 | J39: 2 | K39: 6 | L39: https://drive.google.com/open?id=1Q5fHAFARB8bSfjDJVuGnrGya7X7xvUb- | M39: 085801199373, 085741322241 | N39: 085817703765, 085755609086, 085856742001, | O39: https://drive.google.com/open?id=18FPI3y85s4T8sjTJfq3NTEfTClUdoAv2 | P39: 3
A40: 46209.541 | B40: 46207 | C40: East Java (Jatim) | D40: Surabaya | E40: Dimas | F40: Savira cell | G40: https://drive.google.com/open?id=1daU6twRF75vMguIfPJWXcptez0_crZcg | H40: 9 | J40: 2 | K40: 4 | L40: https://drive.google.com/open?id=138TIiWGH0zMcdC7bXJJRquOKzDV657jJ | M40: 085801199358 | N40: 085784020541, 085649526465, 085814755538, 0895639170022 | O40: https://drive.google.com/open?id=1oAYcxi6_D4Eatv8udLhArQIbN1WjM9uB | P40: 2
...

Sheet Dashboard

Sheet Pivot Table 2
K1: Total Achievement | N1: Region
K2: =SUM(H2:J2) -> 0 | N2: Bali Nusra | O2: Central Java (Jateng) | P2: East Java (Jatim) | Q2: Grand Total
K3: =SUM(H3:J3) -> 0 | M3: Jumlah Promotor | N3: 3 | O3: 34 | P3: 24 | Q3: 61
K4: =SUM(H4:J4) -> 0
K5: =SUM(H5:J5) -> 18
K6: =SUM(H6:J6) -> 18
K7: =SUM(H7:J7) -> 6
K8: =SUM(H8:J8) -> 6
K9: =SUM(H9:J9) -> 65
K10: =SUM(H10:J10) -> 42
K11: =SUM(H11:J11) -> 39
K12: =SUM(H12:J12) -> 0
K13: =SUM(H13:J13) -> 79
K14: =SUM(H14:J14) -> 79
K15: =SUM(H15:J15) -> 30
... K60: =SUM(H60:J60) -> 11

Sheet !All Circle 
B1: REPORT ACCUMULATION ACHIEVEMENT PROMOTOR
B2: Region | C2: RGE | D2: Area Penempatan | E2: Jumlah Promotor | F2: Edukasi Total | G2: Rebuy Total | H2: Akuisisi Total | N2: KPI Targeted Promotor for All Region | W2: Performance Promotor
B3: Central Java | C3: Yogie | D3: Yogyakarta | E3: 5 | F3: =X14 -> 922 | G3: =Y14 -> 18 | H3: =Z14 -> 128 | K3: Region | L3: Area Penempatan | M3: COUNTUNIQUE of Nama Promotor | N3: Region | O3: RGE | P3: Area Penempatan | Q3: Targeted New Acquisitions | R3: Targeted Rebuy | S3: Performance Acqusition | T3: Performance Rebuy
C4: Fitri | D4: Solo | E4: 4 | F4: =X13 -> 632 | G4: =Y13 -> 69 | H4: =Z13 -> 100 | K4: Bali Nusra | L4: Denpasar | M4: 1 | N4: Wahyudi | O4: Yogie | P4: Yogyakarta | Q4: =M11*100 -> 1100 | R4: =200*E3 -> 1000 | S4: =(Z14/Q4) -> 0.11636364 | T4: =Y14/R4 -> 0.018
C5: Wahyudi | D5: Semarang | E5: 6 | F5: =X11 -> 1756 | G5: =Y11 -> 327.58182 | H5: =Z11 -> 236.70909 | L5: Gianyar | M5: 1 | O5: Fitri | P5: Solo | Q5: =M10*100 -> 500 | R5: =200*E4 -> 800 | S5: =Z13/Q5 -> 0.2 | T5: =Y13/R5 -> 0.08625
C6: Lingga | D6: Sleman | E6: 4 | F6: =X12 -> 498 | G6: =Y12 -> 55 | H6: =Z12 -> 91 | L6: Singaraja | M6: 1 | O6: Vacant | P6: Semarang | Q6: =M8*100 -> 1200 | R6: =200*E5 -> 1200 | S6: =Z11/Q6 -> 0.19725758 | T6: =Y11/R6 -> 0.27298485
C7: TOTAL | E7: 19 | F7: =SUM(F3:F6) -> 3808 | G7: =SUM(G3:G6) -> 469.58182 | H7: =SUM(H3:H6) -> 555.70909 | K7: Bali Nusra Total | M7: 3 | O7: Lingga | P7: Sleman | Q7: =M9*100 -> 700 | R7: =200*E6 -> 800 | S7: =Z12/Q7 -> 0.13 | T7: =Y12/R7 -> 0.06875
B8: East Java | C8: Melody | D8: Surabaya | E8: 7 | F8: =X28 -> 870.75 | G8: =Y28 -> 353.79091 | H8: =Z28 -> 156.85455 | K8: Central Java (Jateng) | L8: Semarang | M8: 12 | O8: TOTAL | Q8: =SUM(Q4:Q7) -> 3500 | R8: =SUM(R4:R7) -> 3800 | S8: =Z15/Q8 -> 0.15877403 | T8: =Y15/R8 -> 0.12357416
C9: Fendi | D9: Malang | E9: 5 | F9: =X27 -> 987.5 | G9: =Y27 -> 209.52727 | H9: =Z27 -> 65.236364 | L9: Sleman | M9: 7 | N9: East Java | O9: Melody | P9: Surabaya | Q9: =M15*100 -> 1100 | R9: =200*E8 -> 1400 | S9: =Z28/Q9 -> 0.14259504 | T9: =Y28/R9 -> 0.25270779 | W9: Central Java
C10: Rizal | D10: Jember | E10: 5 | F10: =X26 -> 1005 | G10: =Y26 -> 59 | H10: =Z26 -> 46 | L10: Solo | M10: 5 | O10: Fendi | P10: Malang | Q10: =M14*100 -> 500 | R10: =200*E9 -> 1000 | S10: =Z27/Q10 -> 0.13047273 | T10: =Y27/R10 -> 0.20952727 | W10: Area Penempatan | X10: Edukasi | Y10: Rebuy | Z10: Akusisi | AA10: Aktivasi Gemini
C11: TOTAL | E11: 17 | F11: =SUM(F7:F10) -> 6671.25 | G11: =SUM(G7:G10) -> 1091.9 | H11: =SUM(H7:H10) -> 823.8 | L11: Yogyakarta | M11: 11 | O11: Rizal | P11: Jember | Q11: =M13*100 -> 800 | R11: =200*E10 -> 1000 | S11: =Z26/Q11 -> 0.0575 | T11: =Y26/R11 -> 0.059 | W11: Semarang | X11: 1756 | Y11: 327.58182 | Z11: 236.70909 | AA11: 829.94545
B12: Bali Nusra | C12: Maria | D12: Denpasar | E12: 4 | F12: =X19 -> 30 | G12: =Y19 -> 0 | H12: =Z19 -> 8 | K12: Central Java (Jateng) Total | M12: 34 | O12: TOTAL | Q12: =SUM(Q8:Q11) -> 5900 | R12: =SUM(R9:R11) -> 3400 | S12: =Z29/Q12 -> 0.045439137 | T12: =Y29/R12 -> 0.18303476 | W12: Sleman | X12: 498 | Y12: 55 | Z12: 91 | AA12: 101
C13: Dewa | D13: Gianyar | E13: 2 | F13: =X20 -> 4 | G13: =Y20 -> 2 | H13: =Z20 -> 4 | K13: East Java (Jatim) | L13: Jember | M13: 8 | N13: Bali Nusra | O13: Maria | P13: Denpasar | Q13: =M4*100 -> 100 | R13: =200*E12 -> 800 | S13: =Z19/Q13 -> 0.08 | T13: =Y19/R13 -> 0 | W13: Solo | X13: 632 | Y13: 69 | Z13: 100 | AA13: 261
C14: Diswan | D14: Badung | E14: 2 | F14: 0 | G14: 0 | H14: 0 | L14: Malang | M14: 5 | O14: Dewa | P14: Gianyar | Q14: =M5*100 -> 100 | R14: =200*E13 -> 400 | S14: =Z20/Q14 -> 0.04 | T14: =Y20/R14 -> 0.005 | W14: Yogyakarta | X14: 922 | Y14: 18 | Z14: 128 | AA14: 161
C15: Afan | D15: Singaraja | E15: 2 | F15: =X21 -> 14 | G15: =Y21 -> 0 | H15: =Z21 -> 14 | L15: Surabaya | M15: 11 | O15: Diswan | P15: Badung | Q15: =E14*100 -> 200 | R15: =200*E14 -> 400 | S15: 0 | T15: 0 | W15: Grand Total | X15: 3808 | Y15: 469.58182 | Z15: 555.70909 | AA15: 1352.9455
C16: TOTAL | E16: =SUM(E12:E15) -> 10 | F16: =SUM(F12:F15) -> 48 | G16: =SUM(G12:G15) -> 2 | H16: =SUM(H12:H15) -> 26 | K16: East Java (Jatim) Total | M16: 24 | O16: Afan | P16: Singaraja | Q16: =M6*100 -> 100 | R16: =200*E15 -> 400 | S16: =Z21/Q16 -> 0.14 | T16: =Y22/R16 -> 0.005 | W16: per grand total | X16: =X15/X7 -> #DIV/0! | Y16: =Y15/Y7 -> #DIV/0! | Z16: =Z15/Z7 -> #DIV/0! | AA16: =AA15/AA7 -> #DIV/0!
B17: Total Circle Java | E17: =SUM(E7+E11+E16) -> 46 | F17: =F7+F11+F16 -> 10527.25 | G17: =G16+G11+G7 -> 1563.4818 | H17: =H16+H11+H7 -> 1405.5091 | K17: Region | L17: Area Penempatan | M17: 1 | O17: TOTAL | Q17: =SUM(Q13:Q16) -> 500 | R17: =SUM(R13:R16) -> 2000 | S17: =Z22/Q17 -> 0.052 | T17: =Y22/R17 -> 0.001 | W17: Bali Nusra
K18: Region Total | M18: 1 | N18: Rebuy | O18: 200 | Q18: Upselling Activations | R18: 200 | W18: Area Penempatan | X18: Edukasi | Y18: Rebuy | Z18: Akusisi | AA18: Aktivasi Gemini
K19: Grand Total | M19: 62 | W19: Denpasar | X19: 30 | Y19: 0 | Z19: 8 | AA19: 10
W20: Gianyar | X20: 4 | Y20: 2 | Z20: 4 | AA20: 0
O21: Week 1 | P21: Week 2 | Q21: Week 3 | R21: Week 4 | W21: Singaraja | X21: 14 | Y21: 0 | Z21: 14 | AA21: 14
W22: Grand Total | X22: 48 | Y22: 2 | Z22: 26 | AA22: 24
W23: per grand total | X23: =X22/X14 -> 0.052060738 | Y23: =Y22/Y14 -> 0.11111111 | Z23: =Z22/Z14 -> 0.203125 | AA23: =AA22/AA14 -> 0.14906832
W24: East Java
W25: Area Penempatan | X25: Edukasi | Y25: Rebuy | Z25: Akusisi | AA25: Aktivasi Gemini
W26: Jember | X26: 1005 | Y26: 59 | Z26: 46 | AA26: 229
W27: Malang | X27: 987.5 | Y27: 209.52727 | Z27: 65.236364 | AA27: 312.07273
W28: Surabaya | X28: 870.75 | Y28: 353.79091 | Z28: 156.85455 | AA28: 358.38182
W29: Grand Total | X29: 2863.25 | Y29: 622.31818 | Z29: 268.09091 | AA29: 899.45455
W30: per grand total | X30: =X29/X7 -> #DIV/0! | Y30: =Y29/Y7 -> #DIV/0! | Z30: =Z29/Z7 -> #DIV/0! | AA30: =AA29/AA7 -> #DIV/0!

Sheet Promotor Rank
H2: Accumulation | I2: Ranking East Java
H3: =SUM(C3:F3) -> 471.77727 | I3: 1 | J3: =IFERROR(__xludf.DUMMYFUNCTION("QUERY(B2:H23,""SELECT B,H ORDER BY H DESC LIMIT 5"",0)"),"Grand Total") -> Grand Total | K3: =IFERROR(__xludf.DUMMYFUNCTION("""COMPUTED_VALUE"""),4653.113636363637) -> 4653.1136
H4: =SUM(C4:F4) -> 407.33636 | I4: 2 | J4: =IFERROR(__xludf.DUMMYFUNCTION("""COMPUTED_VALUE"""),"Adit") -> Adit | K4: =IFERROR(__xludf.DUMMYFUNCTION("""COMPUTED_VALUE"""),471.7772727272732) -> 471.77727
H5: =SUM(C5:F5) -> 311 | I5: 3 | J5: =IFERROR(__xludf.DUMMYFUNCTION("""COMPUTED_VALUE"""),"aulia farah ") -> aulia farah | K5: =IFERROR(__xludf.DUMMYFUNCTION("""COMPUTED_VALUE"""),407.3363636363638) -> 407.33636
H6: =SUM(C6:F6) -> 264 | I6: 4 | J6: =IFERROR(__xludf.DUMMYFUNCTION("""COMPUTED_VALUE"""),"vina lailatul") -> vina lailatul | K6: =IFERROR(__xludf.DUMMYFUNCTION("""COMPUTED_VALUE"""),387.0) -> 387
H7: =SUM(C7:F7) -> 86 | I7: 5 | J7: =IFERROR(__xludf.DUMMYFUNCTION("""COMPUTED_VALUE"""),"Fandi Ahmad") -> Fandi Ahmad | K7: =IFERROR(__xludf.DUMMYFUNCTION("""COMPUTED_VALUE"""),384.0) -> 384
H8: =SUM(C8:F8) -> 160
H9: =SUM(C9:F9) -> 120
H10: =SUM(C10:F10) -> 176
H11: =SUM(C11:F11) -> 384
H12: =SUM(C12:F12) -> 334
H13: =SUM(C13:F13) -> 25
H14: =SUM(C14:F14) -> 204
H15: =SUM(C15:F15) -> 261
H16: =SUM(C16:F16) -> 1
H17: =SUM(C17:F17) -> 140
H18: =SUM(C18:F18) -> 308
H19: =SUM(C19:F19) -> 211
... H23: =SUM(C23:F23) -> 4653.1136
H27: Accumulation | I27: Ranking Central Java
H28: =SUM(D28:G28) -> 94.236364 | I28: 1 | J28: =IFERROR(__xludf.DUMMYFUNCTION("QUERY(B27:H62,""SELECT C,H ORDER BY H DESC LIMIT 5"",0)"),"") | K28: =IFERROR(__xludf.DUMMYFUNCTION("""COMPUTED_VALUE"""),1229.0) -> 1229
H29: =SUM(D29:G29) -> 274 | I29: 2 | K29: =IFERROR(__xludf.DUMMYFUNCTION("""COMPUTED_VALUE"""),1062.0) -> 1062
H30: =SUM(D30:G30) -> 259 | I30: 3 | J30: =IFERROR(__xludf.DUMMYFUNCTION("""COMPUTED_VALUE"""),"Zazha Adelia Soetikno") -> Zazha Adelia Soetikno | K30: =IFERROR(__xludf.DUMMYFUNCTION("""COMPUTED_VALUE"""),616.0) -> 616
H31: =SUM(D31:G31) -> 499 | I31: 4 | J31: =IFERROR(__xludf.DUMMYFUNCTION("""COMPUTED_VALUE"""),"M Mikail Azka (Kaka)") -> M Mikail Azka (Kaka) | K31: =IFERROR(__xludf.DUMMYFUNCTION("""COMPUTED_VALUE"""),499.0) -> 499
H32: =SUM(D32:G32) -> 336 | I32: 5 | J32: =IFERROR(__xludf.DUMMYFUNCTION("""COMPUTED_VALUE"""),"Nurul Hidayah") -> Nurul Hidayah | K32: =IFERROR(__xludf.DUMMYFUNCTION("""COMPUTED_VALUE"""),477.0) -> 477
H33: =SUM(D33:G33) -> 340
H34: =SUM(D34:G34) -> 477
H35: =SUM(D35:G35) -> 94
H36: =SUM(D36:G36) -> 616
H37: =SUM(D37:G37) -> 161
H40: =SUM(D40:G40) -> 13
H41: =SUM(D41:G41) -> 161
H42: =SUM(D42:G42) -> 232
H43: =SUM(D43:G43) -> 145
H44: =SUM(D44:G44) -> 62
H47: =SUM(D47:G47) -> 313
H48: =SUM(D48:G48) -> 389
... H61: =SUM(D61:G61) -> 1229
H64: Accumulation | I64: Ranking Bali Nusra
H65: =SUM(D65:G65) -> 48 | I65: 1 | J65: =IFERROR(__xludf.DUMMYFUNCTION("QUERY(C65:H71,""SELECT C,H ORDER BY H DESC LIMIT 5"",0)"),"Ryan shobwatur rizal") -> Ryan shobwatur rizal | K65: =IFERROR(__xludf.DUMMYFUNCTION("""COMPUTED_VALUE"""),48.0) -> 48
...

Sheet Promotor-Information
A2: Alif | B2: Central Java | F2: East Java | J2: Bali Nusra
A3: Updated Promotor | B3: BRANCH | C3: PROMOTOR IM3 | D3: PROMOTOR 3ID | F3: BRANCH | G3: PROMOTOR IM3 | H3: PROMOTOR 3ID | J3: BRANCH | K3: PROMOTOR IM3 | L3: PROMOTOR 3ID
B4: Yogyakarta | C4: Vian Erviana Reilyani | D4: Tasya Intan Maharani | F4: Surabaya | G4: Fira Daniarsa putri | H4: Khafied | J4: Denpasar | K4: Ryan Shobwatur (resign 8 jul)
C5: Nia Febriyanti | D5: Fransisca Meita W | G5: Vina Lailatul | H5: Arifa dziya | J5: Singaraja | K5: Lubna Intan
C6: Natalia Rizki Aria Wijaya | D6: Hafis Yosya Pradana | G6: Aditya Pratama | H6: Rizal (mundur per hari ini) | J6: Gianyar | K6: Novik Resya (resign 01/07/26)
C7: Sugiyanti | G7: Chestya Sayyidina (resign 02/07/26) | J7: Total | K7: 2 | L7: =COUNTA(L4:L6) -> 0
C8: Rebeka Tiara Busono | G8: Dimas Faizal
B9: Semarang | C9: Nurul Hidayah | D9: Devi Kumala Novianti | G9: M Raffi
C10: M Mikail Azka (Kaka) | D10: Zumalia Suci Retnowati | G10: Endah Widowati
C11: Zazha Adelia Soetikno | D11: Bagus Nurul Khamid | G11: Emillia Margaretha
C12: Ika Mayestika | D12: Septy Maulida | F12: Malang | G12: Fandi ahmad (resign 01/07/26) | H12: Erni Farida
C13: NOOR ROOFI JUNMANTINI | G13: Destya Kamila | H13: Tegas Galang Pamungkas
C14: Neha naura herwin | G14: Aulia Farah | H14: Penggalang Siswoyo
B15: Solo | C15: Retha | D15: Keiky Junieta Sari | G15: M Rheiza Prasanjaya | H15: Alviyan G
C16: Rizky pratama dewi | G16: Predika Tri Aditya
C17: Eva diana | F17: Jember | G17: Ulfa Faizatul Laily
C18: Nur Eka Junianti Harahap | G18: Putri
B19: Sleman | C19: SYAHRUL HADI MAULANA | G19: Resita putri anggraini
C20: Nila Mustika Sri | G20: Dewi Kumalasari
C21: Ganis Ghaniyy Rohim | G21: Tiara Putri Ramadhani
C22: Ika adhelia | G22: Dinda Nur A
C23: Erlis Krisnawati | F23: Sidoarjo | H23: Nanda Dwi
C24: Viantrini | H24: Imanuel Levi
C25: Lia Kurniawaty | H25: Yani (mundur per hari ini)
B26: Purwokerto | D26: Aufa Amaliatun | F26: Total | G26: 17 | H26: 8
B29: Total | C29: =COUNTA(C4:C28) -> 22 | D29: 6
C31: Tanda mundur/ Belum Fiks

Sheet Detail1-Denpasar-Ryan shobwatur
A1: Timestamp | B1: Hari & Tanggal | C1: Region | D1: Area Penempatan | E1: Nama Promotor | F1: Nama Outlet | G1: Upload Foto Kehadiran dengan Time Stamp (untuk Bukti Kehadiran) | H1: Jumlah edukasi - isi dengan angka. Cth: 2 (Target 30 hari: 600 edukasi Gemini) | I1: Bukti Foto Edukasi | J1: Jumlah penjualan Kartu Perdana - isi dengan angka. Cth: 2 (Target 30 hari: 100 Kartu Perdana terjual) | K1: Jumlah penjualan Paket Isi Ulang - isi dengan angka. Cth: 2 (Target 30 hari: 200 Paket Isi Ulang terjual) | L1: Bukti Foto Penjualan | M1: List No. HP yang terjual | N1: List No. HP yang melakukan isi ulang | O1: Upload Foto Kepulangan dengan Time Stamp (untuk Bukti Kepulangan) | P1: Jumlah aktivasi Gemini dari orang yang diedukasi | Q1: Hari & Tanggal 2 | R1: Brand | S1: Column 1
A2: 46206.855 | B2: 46206 | C2: Bali Nusra | D2: Denpasar | E2: Ryan shobwatur rizal | F2: TFT cell | G2: https://drive.google.com/open?id=15p1hHEvL_6drhRD645Bjo5cManPcBihC | H2: 10 | J2: 0 | K2: 0 | L2: https://drive.google.com/open?id=19EyudNkvCkHwmABxi5spE9V7lMT40ZNf | M2: 0 | N2: 0 | O2: https://drive.google.com/open?id=1fTvxRnm1SyQyvWRFXU9ddipA4czUUJQx | P2: 0
A3: 46203.694 | B3: 46203 | C3: Bali Nusra | D3: Denpasar | E3: Ryan shobwatur rizal | F3: TFT Cell | G3: https://drive.google.com/open?id=1DcXTeN8m_rKDeMnoEBJC57p0JckEVDHu | H3: 10 | J3: 3 | K3: 0 | L3: https://drive.google.com/open?id=1XehGREVNtETt2_ODnEWA-e8Wa8CJTWx9 | M3: 085728009454 085602898261 085602898260 | N3: 0 | O3: https://drive.google.com/open?id=1XGA6qYgnM9e0DYfwvMLbkbZGjpOKnvWL | P3: 3
A4: 46204.734 | B4: 46204 | C4: Bali Nusra | D4: Denpasar | E4: Ryan shobwatur rizal | F4: TFT cell | G4: https://drive.google.com/open?id=1vPcYfeSF3J_xCVfeTKfyrxExrXk7zWv5 | H4: 5 | J4: 2 | K4: 0 | L4: https://drive.google.com/open?id=1CQYc1OedGfnT5x4m7H5Lps1jh5JphR_h | M4: 085602899546 085602899545 | N4: 0 | O4: https://drive.google.com/open?id=1WzeTQ9Y30UxC2RrTtRX01wPYZ2S0zQch | P4: 5
A5: 46205.881 | B5: 46205 | C5: Bali Nusra | D5: Denpasar | E5: Ryan shobwatur rizal | F5: TFT cell | G5: https://drive.google.com/open?id=1xjiwCU17Pjohd0XMzynVILY9MNm1nNdQ | H5: 5 | J5: 3 | K5: 0 | L5: https://drive.google.com/open?id=1XUhrOQUh7kdjQDxGbRZqbUUTY4lXxb2Y | M5: 085602899544 085602899539 085602899540 | N5: 0 | O5: https://drive.google.com/open?id=1pgM2h7OFs3P6h1aX7rjkyd6oXI7JwGUA | P5: 2

Sheet Summary CJ
J2: Edukasi | M2: Rebuy | P2: Acquisition | S2: GEMINI
H3: RGE | I3: Area Penempatan | J3: Target | K3: Actual | L3: % ACh | M3: Target | N3: Actual | O3: % ACh | P3: Target | Q3: Actual | R3: % ACh | S3: Claim
H4: Sekar | I4: Yogyakarta | J4: =SUMifs(J$12:J42,$C$12:$C42,$I4,$G$12:$G42,"true") -> 3600 | K4: =SUMifs(K$12:K42,$C$12:$C42,$I4,$G$12:$G42,"true") -> 822 | L4: =K4/J4 -> 0.22833333 | M4: =SUMifs(M$12:M42,$C$12:$C42,$I4,$G$12:$G42,"true") -> 1200 | N4: =SUMifs(N$12:N42,C$12:C42,$I4,G$12:G42,"true") -> 7 | O4: =N4/M4 -> 0.0058333333 | P4: =SUMifs(P$12:P42,$C$12:$C42,$I4,$G$12:$G42,"true") -> 600 | Q4: =SUMifs(Q$12:Q42,C$12:C42,$I4,G$12:G42,"true") -> 114 | R4: =Q4/P4 -> 0.19 | S4: =SUMifs(S$12:S42,$C$12:$C42,$I4,$G$12:$G42,"true") -> 155
H5: Fitri | I5: Solo | J5: =SUMifs(J$12:J42,$C$12:$C42,$I5,$G$12:$G42,"true") -> 3000 | K5: =SUMifs(K$12:K42,C$12:C42,$I5,G$12:G42,"true") -> 622 | L5: =K5/J5 -> 0.20733333 | M5: =SUMifs(M$12:M42,$C$12:$C42,$I5,$G$12:$G42,"true") -> 1000 | N5: =SUMifs(N$12:N42,C$12:C42,$I5,G$12:G42,"true") -> 69 | O5: =N5/M5 -> 0.069 | P5: =SUMifs(P$12:P42,$C$12:$C42,$I5,$G$12:$G42,"true") -> 500 | Q5: =SUMifs(Q$12:Q42,C$12:C42,$I5,G$12:G42,"true") -> 98 | R5: =Q5/P5 -> 0.196 | S5: =SUMifs(S$12:S42,$C$12:$C42,$I5,$G$12:$G42,"true") -> 251
H6: Vacant | I6: Semarang | J6: =SUMifs(J$12:J42,$C$12:$C42,$I6,$G$12:$G42,"true") -> 6000 | K6: =SUMifs(K$12:K42,C$12:C42,$I6,G$12:G42,"true") -> 1756 | L6: =K6/J6 -> 0.29266667 | M6: =SUMifs(M$12:M42,$C$12:$C42,$I6,$G$12:$G42,"true") -> 2000 | N6: =SUMifs(N$12:N42,C$12:C42,$I6,G$12:G42,"true") -> 327.58182 | O6: =N6/M6 -> 0.16379091 | P6: =SUMifs(P$12:P42,$C$12:$C42,$I6,$G$12:$G42,"true") -> 1000 | Q6: =SUMifs(Q$12:Q42,C$12:C42,$I6,G$12:G42,"true") -> 236.70909 | R6: =Q6/P6 -> 0.23670909 | S6: =SUMifs(S$12:S42,$C$12:$C42,$I6,$G$12:$G42,"true") -> 829.94545
H7: Lingga | I7: Sleman | J7: =SUMifs(J$12:J42,$C$12:$C42,$I7,$G$12:$G42,"true") -> 3000 | K7: =SUMifs(K$12:K42,C$12:C42,$I7,G$12:G42,"true") -> 527 | L7: =K7/J7 -> 0.17566667 | M7: =SUMifs(M$12:M42,$C$12:$C42,$I7,$G$12:$G42,"true") -> 1000 | N7: =SUMifs(N$12:N42,C$12:C42,$I7,G$12:G42,"true") -> 56 | O7: =N7/M7 -> 0.056 | P7: =SUMifs(P$12:P42,$C$12:$C42,$I7,$G$12:$G42,"true") -> 500 | Q7: =SUMifs(Q$12:Q42,C$12:C42,$I7,G$12:G42,"true") -> 92 | R7: =Q7/P7 -> 0.184 | S7: =SUMifs(S$12:S42,$C$12:$C42,$I7,$G$12:$G42,"true") -> 102 | U7: date
H8: Central JAVA | J8: =sum(J4:J7) -> 15600 | K8: =sum(K4:K7) -> 3727 | L8: =K8/J8 -> 0.23891026 | M8: =sum(M4:M7) -> 5200 | N8: =sum(N4:N7) -> 459.58182 | O8: =N8/M8 -> 0.088381119 | P8: =sum(P4:P7) -> 2600 | Q8: =sum(Q4:Q7) -> 540.70909 | R8: =Q8/P8 -> 0.20796503 | S8: =sum(S4:S7) -> 1337.9455 | U8: 46211
J10: Edukasi | M10: Rebuy | P10: Acquisition | S10: GEMINI | U10: QUICK COUNT ( REAL TIME)
C11: BRANCH | D11: KAMPUS | E11: OUTLET | F11: PROMOTOR | G11: STATUS ONBOARD | H11: TANGGAL ONBOARD | I11: Masa Kerja | J11: Target | K11: Actual | L11: % ACh | M11: Target | N11: Actual | O11: % ACh | P11: Target | Q11: Actual | R11: % ACh | S11: Claim | U11: EDUKASI | V11: REBUY | W11: AKUISISI | X11: GEMINI
A12: 1 | B12: 1 | C12: Yogyakarta | D12: UAD | E12: {=xlookup(F12,'Form Responses 1'!E:E,'Form Responses 1'!F:F,"")} -> Jogja card | F12: Vian Erviana Reilyani | G12: TRUE | H12: 46195 | I12: =TODAY()-H12 -> 17 | J12: 600 | K12: =sumifs('Form Responses 1'!H:H,'Form Responses 1'!E:E,F12) -> 218 | L12: =K12/J12 -> 0.36333333 | M12: 200 | N12: =sumifs('Form Responses 1'!K:K,'Form Responses 1'!E:E,F12) -> 7 | O12: =N12/M12 -> 0.035 | P12: 100 | Q12: =sumifs('Form Responses 1'!J:J,'Form Responses 1'!E:E,F12) -> 49 | R12: =Q12/P12 -> 0.49 | S12: =sumifs('Form Responses 1'!P:P,'Form Responses 1'!E:E,F12) -> 59 | U12: =sumifs('Form Responses 1'!H:H,'Form Responses 1'!E:E,F12,'Form Responses 1'!$B:$B,$U$8) -> 0 | V12: =sumifs('Form Responses 1'!K:K,'Form Responses 1'!E:E,F12,'Form Responses 1'!$B:$B,$U$8) -> 0 | W12: =sumifs('Form Responses 1'!J:J,'Form Responses 1'!E:E,F12,'Form Responses 1'!$B:$B,$U$8) -> 0 | X12: =sumifs('Form Responses 1'!P:P,'Form Responses 1'!E:E,F12,'Form Responses 1'!$B:$B,$U$8) -> 0
A13: 2 | B13: 2 | C13: Yogyakarta | D13: UTY | E13: {=xlookup(F13,'Form Responses 1'!E:E,'Form Responses 1'!F:F,"")} -> SKA CELL | F13: Nia Febriyanti | G13: TRUE | H13: 46195 | I13: =TODAY()-H13 -> 17 | J13: 600 | K13: =sumifs('Form Responses 1'!H:H,'Form Responses 1'!E:E,F13) -> 176 | L13: =K13/J13 -> 0.29333333 | M13: 200 | N13: =sumifs('Form Responses 1'!K:K,'Form Responses 1'!E:E,F13) -> 0 | O13: =N13/M13 -> 0 | P13: 100 | Q13: =sumifs('Form Responses 1'!J:J,'Form Responses 1'!E:E,F13) -> 34 | R13: =Q13/P13 -> 0.34 | S13: =sumifs('Form Responses 1'!P:P,'Form Responses 1'!E:E,F13) -> 42 | U13: =sumifs('Form Responses 1'!H:H,'Form Responses 1'!E:E,F13,'Form Responses 1'!$B:$B,$U$8) -> 0 | V13: =sumifs('Form Responses 1'!K:K,'Form Responses 1'!E:E,F13,'Form Responses 1'!$B:$B,$U$8) -> 0 | W13: =sumifs('Form Responses 1'!J:J,'Form Responses 1'!E:E,F13,'Form Responses 1'!$B:$B,$U$8) -> 0 | X13: =sumifs('Form Responses 1'!P:P,'Form Responses 1'!E:E,F13,'Form Responses 1'!$B:$B,$U$8) -> 0
A14: 3 | B14: 3 | C14: Yogyakarta | D14: PGRI | E14: {=xlookup(F14,'Form Responses 1'!E:E,'Form Responses 1'!F:F,"")} -> Malioboro | F14: Natalia Rizki Aria Wijaya | G14: TRUE | H14: 46200 | I14: =TODAY()-H14 -> 12 | J14: 600 | K14: =sumifs('Form Responses 1'!H:H,'Form Responses 1'!E:E,F14) -> 220 | L14: =K14/J14 -> 0.36666667 | M14: 200 | N14: =sumifs('Form Responses 1'!K:K,'Form Responses 1'!E:E,F14) -> 0 | O14: =N14/M14 -> 0 | P14: 100 | Q14: =sumifs('Form Responses 1'!J:J,'Form Responses 1'!E:E,F14) -> 23 | R14: =Q14/P14 -> 0.23 | S14: =sumifs('Form Responses 1'!P:P,'Form Responses 1'!E:E,F14) -> 35 | U14: =sumifs('Form Responses 1'!H:H,'Form Responses 1'!E:E,F14,'Form Responses 1'!$B:$B,$U$8) -> 0 | V14: =sumifs('Form Responses 1'!K:K,'Form Responses 1'!E:E,F14,'Form Responses 1'!$B:$B,$U$8) -> 0 | W14: =sumifs('Form Responses 1'!J:J,'Form Responses 1'!E:E,F14,'Form Responses 1'!$B:$B,$U$8) -> 0 | X14: =sumifs('Form Responses 1'!P:P,'Form Responses 1'!E:E,F14,'Form Responses 1'!$B:$B,$U$8) -> 0
A15: 5 | B15: 4 | C15: Yogyakarta | D15: ISI | E15: {=xlookup(F15,'Form Responses 1'!E:E,'Form Responses 1'!F:F,"")} -> Public Cell | F15: Sugiyanti | G15: TRUE | H15: 46202 | I15: =TODAY()-H15 -> 10 | J15: 600 | K15: =sumifs('Form Responses 1'!H:H,'Form Responses 1'!E:E,F15) -> 126 | L15: =K15/J15 -> 0.21 | M15: 200 | N15: =sumifs('Form Responses 1'!K:K,'Form Responses 1'!E:E,F15) -> 0 | O15: =N15/M15 -> 0 | P15: 100 | Q15: =sumifs('Form Responses 1'!J:J,'Form Responses 1'!E:E,F15) -> 8 | R15: =Q15/P15 -> 0.08 | S15: =sumifs('Form Responses 1'!P:P,'Form Responses 1'!E:E,F15) -> 8 | U15: =sumifs('Form Responses 1'!H:H,'Form Responses 1'!E:E,F15,'Form Responses 1'!$B:$B,$U$8) -> 0 | V15: =sumifs('Form Responses 1'!K:K,'Form Responses 1'!E:E,F15,'Form Responses 1'!$B:$B,$U$8) -> 0 | W15: =sumifs('Form Responses 1'!J:J,'Form Responses 1'!E:E,F15,'Form Responses 1'!$B:$B,$U$8) -> 0 | X15: =sumifs('Form Responses 1'!P:P,'Form Responses 1'!E:E,F15,'Form Responses 1'!$B:$B,$U$8) -> 0
A16: 6 | B16: 5 | C16: Yogyakarta | D16: UTY | E16: {=xlookup(F16,'Form Responses 1'!E:E,'Form Responses 1'!F:F,"")} -> SKA CELL | F16: Rebeka Tiara Busono | G16: TRUE | H16: 46204 | I16: =TODAY()-H16 -> 8 | J16: 600 | K16: =sumifs('Form Responses 1'!H:H,'Form Responses 1'!E:E,F16) -> 74 | L16: =K16/J16 -> 0.12333333 | M16: 200 | N16: =sumifs('Form Responses 1'!I:I,'Form Responses 1'!F:F,G16) -> 0 | O16: =N16/M16 -> 0 | P16: 100 | Q16: =sumifs('Form Responses 1'!J:J,'Form Responses 1'!G:G,H16) -> 0 | R16: =Q16/P16 -> 0 | S16: =sumifs('Form Responses 1'!P:P,'Form Responses 1'!E:E,F16) -> 7 | U16: =sumifs('Form Responses 1'!H:H,'Form Responses 1'!E:E,F16,'Form Responses 1'!$B:$B,$U$8) -> 0 | V16: =sumifs('Form Responses 1'!K:K,'Form Responses 1'!E:E,F16,'Form Responses 1'!$B:$B,$U$8) -> 0 | W16: =sumifs('Form Responses 1'!J:J,'Form Responses 1'!E:E,F16,'Form Responses 1'!$B:$B,$U$8) -> 0 | X16: =sumifs('Form Responses 1'!P:P,'Form Responses 1'!E:E,F16,'Form Responses 1'!$B:$B,$U$8) -> 0
B17: 6 | C17: Yogyakarta | F17: Tasya Intan Maharani | G17: TRUE | H17: 46210 | J17: 600 | K17: =sumifs('Form Responses 1'!H:H,'Form Responses 1'!E:E,F17) -> 8 | L17: =K17/J17 -> 0.013333333 | M17: 200 | N17: =sumifs('Form Responses 1'!I:I,'Form Responses 1'!F:F,G17) -> 0 | O17: =N17/M17 -> 0 | P17: 100 | Q17: =sumifs('Form Responses 1'!J:J,'Form Responses 1'!G:G,H17) -> 0 | R17: =Q17/P17 -> 0 | S17: =sumifs('Form Responses 1'!P:P,'Form Responses 1'!E:E,F17) -> 4 | U17: =sumifs('Form Responses 1'!H:H,'Form Responses 1'!E:E,F17,'Form Responses 1'!$B:$B,$U$8) -> 5 | V17: =sumifs('Form Responses 1'!K:K,'Form Responses 1'!E:E,F17,'Form Responses 1'!$B:$B,$U$8) -> 1 | W17: =sumifs('Form Responses 1'!J:J,'Form Responses 1'!E:E,F17,'Form Responses 1'!$B:$B,$U$8) -> 0 | X17: =sumifs('Form Responses 1'!P:P,'Form Responses 1'!E:E,F17,'Form Responses 1'!$B:$B,$U$8) -> 2
B18: 7 | C18: Yogyakarta | F18: Fransisca Meita W | G18: FALSE | H18: TUNGGU KONFIRM | J18: 600 | K18: =sumifs('Form Responses 1'!H:H,'Form Responses 1'!E:E,F18) -> 0 | L18: =K18/J18 -> 0 | M18: 200 | N18: =sumifs('Form Responses 1'!I:I,'Form Responses 1'!F:F,G18) -> 0 | O18: =N18/M18 -> 0 | P18: 100 | Q18: =sumifs('Form Responses 1'!J:J,'Form Responses 1'!G:G,H18) -> 0 | R18: =Q18/P18 -> 0 | S18: =sumifs('Form Responses 1'!P:P,'Form Responses 1'!E:E,F18) -> 0 | U18: =sumifs('Form Responses 1'!H:H,'Form Responses 1'!E:E,F18,'Form Responses 1'!$B:$B,$U$8) -> 0 | V18: =sumifs('Form Responses 1'!K:K,'Form Responses 1'!E:E,F18,'Form Responses 1'!$B:$B,$U$8) -> 0 | W18: =sumifs('Form Responses 1'!J:J,'Form Responses 1'!E:E,F18,'Form Responses 1'!$B:$B,$U$8) -> 0 | X18: =sumifs('Form Responses 1'!P:P,'Form Responses 1'!E:E,F18,'Form Responses 1'!$B:$B,$U$8) -> 0
B19: 8 | C19: Yogyakarta | F19: Hafis Yosya Pradana | G19: FALSE | H19: TUNGGU KONFIRM | J19: 600 | K19: =sumifs('Form Responses 1'!H:H,'Form Responses 1'!E:E,F19) -> 0 | L19: =K19/J19 -> 0 | M19: 200 | N19: =sumifs('Form Responses 1'!I:I,'Form Responses 1'!F:F,G19) -> 0 | O19: =N19/M19 -> 0 | P19: 100 | Q19: =sumifs('Form Responses 1'!J:J,'Form Responses 1'!G:G,H19) -> 0 | R19: =Q19/P19 -> 0 | S19: =sumifs('Form Responses 1'!P:P,'Form Responses 1'!E:E,F19) -> 0 | U19: =sumifs('Form Responses 1'!H:H,'Form Responses 1'!E:E,F19,'Form Responses 1'!$B:$B,$U$8) -> 0 | V19: =sumifs('Form Responses 1'!K:K,'Form Responses 1'!E:E,F19,'Form Responses 1'!$B:$B,$U$8) -> 0 | W19: =sumifs('Form Responses 1'!J:J,'Form Responses 1'!E:E,F19,'Form Responses 1'!$B:$B,$U$8) -> 0 | X19: =sumifs('Form Responses 1'!P:P,'Form Responses 1'!E:E,F19,'Form Responses 1'!$B:$B,$U$8) -> 0
A20: 1 | B20: 9 | C20: Semarang | D20: UNNES & UNWAHAS | E20: {=xlookup(F20,'Form Responses 1'!E:E,'Form Responses 1'!F:F,"")} -> Graha Komunika | F20: Nurul Hidayah | G20: TRUE | H20: 46198 | I20: =TODAY()-H20 -> 14 | J20: 600 | K20: =sumifs('Form Responses 1'!H:H,'Form Responses 1'!E:E,F20) -> 280 | L20: =K20/J20 -> 0.46666667 | M20: 200 | N20: =sumifs('Form Responses 1'!K:K,'Form Responses 1'!E:E,F20) -> 39 | O20: =N20/M20 -> 0.195 | P20: 100 | Q20: =sumifs('Form Responses 1'!J:J,'Form Responses 1'!E:E,F20) -> 45 | R20: =Q20/P20 -> 0.45 | S20: =sumifs('Form Responses 1'!P:P,'Form Responses 1'!E:E,F20) -> 113 | U20: =sumifs('Form Responses 1'!H:H,'Form Responses 1'!E:E,F20,'Form Responses 1'!$B:$B,$U$8) -> 0 | V20: =sumifs('Form Responses 1'!K:K,'Form Responses 1'!E:E,F20,'Form Responses 1'!$B:$B,$U$8) -> 0 | W20: =sumifs('Form Responses 1'!J:J,'Form Responses 1'!E:E,F20,'Form Responses 1'!$B:$B,$U$8) -> 0 | X20: =sumifs('Form Responses 1'!P:P,'Form Responses 1'!E:E,F20,'Form Responses 1'!$B:$B,$U$8) -> 0
A21: 2 | B21: 10 | C21: Semarang | D21: Unika | E21: {=xlookup(F21,'Form Responses 1'!E:E,'Form Responses 1'!F:F,"")} -> Amos Cell | F21: M Mikail Azka (Kaka) | G21: TRUE | H21: 46196 | I21: =TODAY()-H21 -> 16 | J21: 600 | K21: =sumifs('Form Responses 1'!H:H,'Form Responses 1'!E:E,F21) -> 272 | L21: =K21/J21 -> 0.45333333 | M21: 200 | N21: =sumifs('Form Responses 1'!K:K,'Form Responses 1'!E:E,F21) -> 43 | O21: =N21/M21 -> 0.215 | P21: 100 | Q21: =sumifs('Form Responses 1'!J:J,'Form Responses 1'!E:E,F21) -> 36 | R21: =Q21/P21 -> 0.36 | S21: =sumifs('Form Responses 1'!P:P,'Form Responses 1'!E:E,F21) -> 148 | U21: =sumifs('Form Responses 1'!H:H,'Form Responses 1'!E:E,F21,'Form Responses 1'!$B:$B,$U$8) -> 23 | V21: =sumifs('Form Responses 1'!K:K,'Form Responses 1'!E:E,F21,'Form Responses 1'!$B:$B,$U$8) -> 6 | W21: =sumifs('Form Responses 1'!J:J,'Form Responses 1'!E:E,F21,'Form Responses 1'!$B:$B,$U$8) -> 0 | X21: =sumifs('Form Responses 1'!P:P,'Form Responses 1'!E:E,F21,'Form Responses 1'!$B:$B,$U$8) -> 16
A22: 3 | B22: 11 | C22: Semarang | D22: UDINUS | E22: {=xlookup(F22,'Form Responses 1'!E:E,'Form Responses 1'!F:F,"")} -> Hi bizz | F22: Zazha Adelia Soetikno | G22: TRUE | H22: 46196 | I22: =TODAY()-H22 -> 16 | J22: 600 | K22: =sumifs('Form Responses 1'!H:H,'Form Responses 1'!E:E,F22) -> 388 | L22: =K22/J22 -> 0.64666667 | M22: 200 | N22: =sumifs('Form Responses 1'!K:K,'Form Responses 1'!E:E,F22) -> 23 | O22: =N22/M22 -> 0.115 | P22: 100 | Q22: =sumifs('Form Responses 1'!J:J,'Form Responses 1'!E:E,F22) -> 60 | R22: =Q22/P22 -> 0.6 | S22: =sumifs('Form Responses 1'!P:P,'Form Responses 1'!E:E,F22) -> 145 | U22: =sumifs('Form Responses 1'!H:H,'Form Responses 1'!E:E,F22,'Form Responses 1'!$B:$B,$U$8) -> 25 | V22: =sumifs('Form Responses 1'!K:K,'Form Responses 1'!E:E,F22,'Form Responses 1'!$B:$B,$U$8) -> 3 | W22: =sumifs('Form Responses 1'!J:J,'Form Responses 1'!E:E,F22,'Form Responses 1'!$B:$B,$U$8) -> 3 | X22: =sumifs('Form Responses 1'!P:P,'Form Responses 1'!E:E,F22,'Form Responses 1'!$B:$B,$U$8) -> 13
A23: 4 | B23: 12 | C23: Semarang | D23: STIE Dharma Putra | E23: {=xlookup(F23,'Form Responses 1'!E:E,'Form Responses 1'!F:F,"")} -> Amos cell | F23: Ika Mayestika | G23: TRUE | H23: 46203 | I23: =TODAY()-H23 -> 9 | J23: 600 | K23: =sumifs('Form Responses 1'!H:H,'Form Responses 1'!E:E,F23) -> 125 | L23: =K23/J23 -> 0.20833333 | M23: 200 | N23: =sumifs('Form Responses 1'!K:K,'Form Responses 1'!E:E,F23) -> 65 | O23: =N23/M23 -> 0.325 | P23: 100 | Q23: =sumifs('Form Responses 1'!J:J,'Form Responses 1'!E:E,F23) -> 15 | R23: =Q23/P23 -> 0.15 | S23: =sumifs('Form Responses 1'!P:P,'Form Responses 1'!E:E,F23) -> 54 | U23: =sumifs('Form Responses 1'!H:H,'Form Responses 1'!E:E,F23,'Form Responses 1'!$B:$B,$U$8) -> 25 | V23: =sumifs('Form Responses 1'!K:K,'Form Responses 1'!E:E,F23,'Form Responses 1'!$B:$B,$U$8) -> 20 | W23: =sumifs('Form Responses 1'!J:J,'Form Responses 1'!E:E,F23,'Form Responses 1'!$B:$B,$U$8) -> 1 | X23: =sumifs('Form Responses 1'!P:P,'Form Responses 1'!E:E,F23,'Form Responses 1'!$B:$B,$U$8) -> 12
A24: 5 | B24: 13 | C24: Semarang | D24: UNDIP | E24: {=xlookup(F24,'Form Responses 1'!E:E,'Form Responses 1'!F:F,"")} -> Hibizz | F24: NOOR ROOFI JUNMANTINI | G24: TRUE | H24: 46203 | I24: =TODAY()-H24 -> 9 | J24: 600 | K24: =sumifs('Form Responses 1'!H:H,'Form Responses 1'!E:E,F24) -> 163 | L24: =K24/J24 -> 0.27166667 | M24: 200 | N24: =sumifs('Form Responses 1'!K:K,'Form Responses 1'!E:E,F24) -> 45 | O24: =N24/M24 -> 0.225 | P24: 100 | Q24: =sumifs('Form Responses 1'!J:J,'Form Responses 1'!E:E,F24) -> 44 | R24: =Q24/P24 -> 0.44 | S24: =sumifs('Form Responses 1'!P:P,'Form Responses 1'!E:E,F24) -> 88 | U24: =sumifs('Form Responses 1'!H:H,'Form Responses 1'!E:E,F24,'Form Responses 1'!$B:$B,$U$8) -> 0 | V24: =sumifs('Form Responses 1'!K:K,'Form Responses 1'!E:E,F24,'Form Responses 1'!$B:$B,$U$8) -> 0 | W24: =sumifs('Form Responses 1'!J:J,'Form Responses 1'!E:E,F24,'Form Responses 1'!$B:$B,$U$8) -> 0 | X24: =sumifs('Form Responses 1'!P:P,'Form Responses 1'!E:E,F24,'Form Responses 1'!$B:$B,$U$8) -> 0
A25: 6 | B25: 14 | C25: Semarang | D25: Polines | E25: {=xlookup(F25,'Form Responses 1'!E:E,'Form Responses 1'!F:F,"")} -> Nafiri pom | F25: NEHA NAURA HERWIN | G25: TRUE | H25: 46203 | J25: 600 | K25: =sumifs('Form Responses 1'!H:H,'Form Responses 1'!E:E,F25) -> 168 | L25: =K25/J25 -> 0.28 | M25: 200 | N25: =sumifs('Form Responses 1'!K:K,'Form Responses 1'!E:E,F25) -> 46 | O25: =N25/M25 -> 0.23 | P25: 100 | Q25: =sumifs('Form Responses 1'!J:J,'Form Responses 1'!E:E,F25) -> 13 | R25: =Q25/P25 -> 0.13 | S25: =sumifs('Form Responses 1'!P:P,'Form Responses 1'!E:E,F25) -> 109 | U25: =sumifs('Form Responses 1'!H:H,'Form Responses 1'!E:E,F25,'Form Responses 1'!$B:$B,$U$8) -> 0 | V25: =sumifs('Form Responses 1'!K:K,'Form Responses 1'!E:E,F25,'Form Responses 1'!$B:$B,$U$8) -> 0 | W25: =sumifs('Form Responses 1'!J:J,'Form Responses 1'!E:E,F25,'Form Responses 1'!$B:$B,$U$8) -> 0 | X25: =sumifs('Form Responses 1'!P:P,'Form Responses 1'!E:E,F25,'Form Responses 1'!$B:$B,$U$8) -> 0
B26: 15 | C26: Semarang | D26: USM | E26: {=xlookup(F26,'Form Responses 1'!E:E,'Form Responses 1'!F:F,"")} -> Susan cell | F26: Septy maulida ( sely ) | G26: TRUE | H26: 46205 | I26: =TODAY()-H26 -> 7 | J26: 600 | K26: =sumifs('Form Responses 1'!H:H,'Form Responses 1'!E:E,F26) -> 49 | L26: =K26/J26 -> 0.081666667 | M26: 200 | N26: =sumifs('Form Responses 1'!K:K,'Form Responses 1'!E:E,F26) -> 4 | O26: =N26/M26 -> 0.02 | P26: 100 | Q26: =sumifs('Form Responses 1'!J:J,'Form Responses 1'!E:E,F26) -> 5 | R26: =Q26/P26 -> 0.05 | S26: =sumifs('Form Responses 1'!P:P,'Form Responses 1'!E:E,F26) -> 36 | U26: =sumifs('Form Responses 1'!H:H,'Form Responses 1'!E:E,F26,'Form Responses 1'!$B:$B,$U$8) -> 18 | V26: =sumifs('Form Responses 1'!K:K,'Form Responses 1'!E:E,F26,'Form Responses 1'!$B:$B,$U$8) -> 1 | W26: =sumifs('Form Responses 1'!J:J,'Form Responses 1'!E:E,F26,'Form Responses 1'!$B:$B,$U$8) -> 1 | X26: =sumifs('Form Responses 1'!P:P,'Form Responses 1'!E:E,F26,'Form Responses 1'!$B:$B,$U$8) -> 6
B27: 16 | C27: Semarang | D27: UIN Walisongo | E27: {=xlookup(F27,'Form Responses 1'!E:E,'Form Responses 1'!F:F,"")} -> Kimo cell | F27: Zumalia Suci Retnowati | G27: TRUE | H27: 46205 | I27: =TODAY()-H27 -> 7 | J27: 600 | K27: =sumifs('Form Responses 1'!H:H,'Form Responses 1'!E:E,F27) -> 135 | L27: =K27/J27 -> 0.225 | M27: 200 | N27: =sumifs('Form Responses 1'!K:K,'Form Responses 1'!E:E,F27) -> 8 | O27: =N27/M27 -> 0.04 | P27: 100 | Q27: =sumifs('Form Responses 1'!J:J,'Form Responses 1'!E:E,F27) -> 3 | R27: =Q27/P27 -> 0.03 | S27: =sumifs('Form Responses 1'!P:P,'Form Responses 1'!E:E,F27) -> 15 | U27: =sumifs('Form Responses 1'!H:H,'Form Responses 1'!E:E,F27,'Form Responses 1'!$B:$B,$U$8) -> 0 | V27: =sumifs('Form Responses 1'!K:K,'Form Responses 1'!E:E,F27,'Form Responses 1'!$B:$B,$U$8) -> 0 | W27: =sumifs('Form Responses 1'!J:J,'Form Responses 1'!E:E,F27,'Form Responses 1'!$B:$B,$U$8) -> 0 | X27: =sumifs('Form Responses 1'!P:P,'Form Responses 1'!E:E,F27,'Form Responses 1'!$B:$B,$U$8) -> 0
B28: 17 | C28: Semarang | D28: UNWAHAZ | E28: Aristo Card | F28: Devi kumala novianti | G28: TRUE | H28: 46205 | I28: =TODAY()-H28 -> 7 | J28: 600 | K28: =sumifs('Form Responses 1'!H:H,'Form Responses 1'!E:E,F28) -> 151 | L28: =K28/J28 -> 0.25166667 | M28: 200 | N28: =sumifs('Form Responses 1'!K:K,'Form Responses 1'!E:E,F28) -> 33 | O28: =N28/M28 -> 0.165 | P28: 100 | Q28: =sumifs('Form Responses 1'!J:J,'Form Responses 1'!E:E,F28) -> 9 | R28: =Q28/P28 -> 0.09 | S28: =sumifs('Form Responses 1'!P:P,'Form Responses 1'!E:E,F28) -> 81 | U28: =sumifs('Form Responses 1'!H:H,'Form Responses 1'!E:E,F28,'Form Responses 1'!$B:$B,$U$8) -> 25 | V28: =sumifs('Form Responses 1'!K:K,'Form Responses 1'!E:E,F28,'Form Responses 1'!$B:$B,$U$8) -> 10 | W28: =sumifs('Form Responses 1'!J:J,'Form Responses 1'!E:E,F28,'Form Responses 1'!$B:$B,$U$8) -> 2 | X28: =sumifs('Form Responses 1'!P:P,'Form Responses 1'!E:E,F28,'Form Responses 1'!$B:$B,$U$8) -> 13
B29: 18 | C29: semarang | D29: UNIMUS | E29: {=xlookup(F29,'Form Responses 1'!E:E,'Form Responses 1'!F:F,"")} -> King Tronik 2 | F29: Bagus Nurul Khamid | G29: TRUE | H29: 46205 | I29: =TODAY()-H29 -> 7 | J29: 600 | K29: =sumifs('Form Responses 1'!H:H,'Form Responses 1'!E:E,F29) -> 25 | L29: =K29/J29 -> 0.041666667 | M29: 200 | N29: =sumifs('Form Responses 1'!K:K,'Form Responses 1'!E:E,F29) -> 21.581818 | O29: =N29/M29 -> 0.10790909 | P29: 100 | Q29: =sumifs('Form Responses 1'!J:J,'Form Responses 1'!E:E,F29) -> 6.7090909 | R29: =Q29/P29 -> 0.067090909 | S29: =sumifs('Form Responses 1'!P:P,'Form Responses 1'!E:E,F29) -> 40.945455 | U29: =sumifs('Form Responses 1'!H:H,'Form Responses 1'!E:E,F29,'Form Responses 1'!$B:$B,$U$8) -> 8 | V29: =sumifs('Form Responses 1'!K:K,'Form Responses 1'!E:E,F29,'Form Responses 1'!$B:$B,$U$8) -> 4 | W29: =sumifs('Form Responses 1'!J:J,'Form Responses 1'!E:E,F29,'Form Responses 1'!$B:$B,$U$8) -> 3 | X29: =sumifs('Form Responses 1'!P:P,'Form Responses 1'!E:E,F29,'Form Responses 1'!$B:$B,$U$8) -> 5
A30: 1 | B30: 19 | C30: Solo | D30: UNS | E30: {=xlookup(F30,'Form Responses 1'!E:E,'Form Responses 1'!F:F,"")} -> AGUDIA Cell | F30: Ika Prawitasari | G30: TRUE | H30: 46195 | I30: =TODAY()-H30 -> 17 | J30: 600 | K30: =sumifs('Form Responses 1'!H:H,'Form Responses 1'!E:E,F30) -> 276 | L30: =K30/J30 -> 0.46 | M30: 200 | N30: =sumifs('Form Responses 1'!K:K,'Form Responses 1'!E:E,F30) -> 13 | O30: =N30/M30 -> 0.065 | P30: 100 | Q30: =sumifs('Form Responses 1'!J:J,'Form Responses 1'!E:E,F30) -> 47 | R30: =Q30/P30 -> 0.47 | S30: =sumifs('Form Responses 1'!P:P,'Form Responses 1'!E:E,F30) -> 53 | U30: =sumifs('Form Responses 1'!H:H,'Form Responses 1'!E:E,F30,'Form Responses 1'!$B:$B,$U$8) -> 0 | V30: =sumifs('Form Responses 1'!K:K,'Form Responses 1'!E:E,F30,'Form Responses 1'!$B:$B,$U$8) -> 0 | W30: =sumifs('Form Responses 1'!J:J,'Form Responses 1'!E:E,F30,'Form Responses 1'!$B:$B,$U$8) -> 0 | X30: =sumifs('Form Responses 1'!P:P,'Form Responses 1'!E:E,F30,'Form Responses 1'!$B:$B,$U$8) -> 0
A31: 2 | B31: 20 | C31: Solo | D31: UMS | E31: {=xlookup(F31,'Form Responses 1'!E:E,'Form Responses 1'!F:F,"")} -> Abiyu cell | F31: Rizky pratama dewi | G31: TRUE | H31: 46195 | I31: =TODAY()-H31 -> 17 | J31: 600 | K31: =sumifs('Form Responses 1'!H:H,'Form Responses 1'!E:E,F31) -> 129 | L31: =K31/J31 -> 0.215 | M31: 200 | N31: =sumifs('Form Responses 1'!K:K,'Form Responses 1'!E:E,F31) -> 7 | O31: =N31/M31 -> 0.035 | P31: 100 | Q31: =sumifs('Form Responses 1'!J:J,'Form Responses 1'!E:E,F31) -> 33 | R31: =Q31/P31 -> 0.33 | S31: =sumifs('Form Responses 1'!P:P,'Form Responses 1'!E:E,F31) -> 43 | U31: =sumifs('Form Responses 1'!H:H,'Form Responses 1'!E:E,F31,'Form Responses 1'!$B:$B,$U$8) -> 0 | V31: =sumifs('Form Responses 1'!K:K,'Form Responses 1'!E:E,F31,'Form Responses 1'!$B:$B,$U$8) -> 0 | W31: =sumifs('Form Responses 1'!J:J,'Form Responses 1'!E:E,F31,'Form Responses 1'!$B:$B,$U$8) -> 0 | X31: =sumifs('Form Responses 1'!P:P,'Form Responses 1'!E:E,F31,'Form Responses 1'!$B:$B,$U$8) -> 0
A32: 3 | B32: 21 | C32: Solo | D32: UTP & AUB | E32: {=xlookup(F32,'Form Responses 1'!E:E,'Form Responses 1'!F:F,"")} -> mox cell | F32: Eva diana | G32: TRUE | H32: 46195 | I32: =TODAY()-H32 -> 17 | J32: 600 | K32: =sumifs('Form Responses 1'!H:H,'Form Responses 1'!E:E,F32) -> 155 | L32: =K32/J32 -> 0.25833333 | M32: 200 | N32: =sumifs('Form Responses 1'!K:K,'Form Responses 1'!E:E,F32) -> 45 | O32: =N32/M32 -> 0.225 | P32: 100 | Q32: =sumifs('Form Responses 1'!J:J,'Form Responses 1'!E:E,F32) -> 16 | R32: =Q32/P32 -> 0.16 | S32: =sumifs('Form Responses 1'!P:P,'Form Responses 1'!E:E,F32) -> 97 | U32: =sumifs('Form Responses 1'!H:H,'Form Responses 1'!E:E,F32,'Form Responses 1'!$B:$B,$U$8) -> 0 | V32: =sumifs('Form Responses 1'!K:K,'Form Responses 1'!E:E,F32,'Form Responses 1'!$B:$B,$U$8) -> 0 | W32: =sumifs('Form Responses 1'!J:J,'Form Responses 1'!E:E,F32,'Form Responses 1'!$B:$B,$U$8) -> 0 | X32: =sumifs('Form Responses 1'!P:P,'Form Responses 1'!E:E,F32,'Form Responses 1'!$B:$B,$U$8) -> 0
A33: 4 | B33: 22 | C33: Solo | D33: UIN RM Said | E33: {=xlookup(F33,'Form Responses 1'!E:E,'Form Responses 1'!F:F,"")} | F33: Nur Eka Junianti Harahap | G33: TRUE | H33: 46195 | I33: =TODAY()-H33 -> 17 | J33: 600 | K33: =sumifs('Form Responses 1'!H:H,'Form Responses 1'!E:E,F33) -> 0 | L33: =K33/J33 -> 0 | M33: 200 | N33: =sumifs('Form Responses 1'!K:K,'Form Responses 1'!E:E,F33) -> 0 | O33: =N33/M33 -> 0 | P33: 100 | Q33: =sumifs('Form Responses 1'!J:J,'Form Responses 1'!E:E,F33) -> 0 | R33: =Q33/P33 -> 0 | S33: =sumifs('Form Responses 1'!P:P,'Form Responses 1'!E:E,F33) -> 0 | U33: =sumifs('Form Responses 1'!H:H,'Form Responses 1'!E:E,F33,'Form Responses 1'!$B:$B,$U$8) -> 0 | V33: =sumifs('Form Responses 1'!K:K,'Form Responses 1'!E:E,F33,'Form Responses 1'!$B:$B,$U$8) -> 0 | W33: =sumifs('Form Responses 1'!J:J,'Form Responses 1'!E:E,F33,'Form Responses 1'!$B:$B,$U$8) -> 0 | X33: =sumifs('Form Responses 1'!P:P,'Form Responses 1'!E:E,F33,'Form Responses 1'!$B:$B,$U$8) -> 0
